<?xml version="1.0" ?>
<!-- =================================================================================== -->
<!-- |    This document was autogenerated by xacro from /home/admin/ros2_ws/src/robotnik_description/robots/rbvogui/rbvogui.urdf.xacro | -->
<!-- |    EDITING THIS FILE BY HAND IS NOT RECOMMENDED                                 | -->
<!-- =================================================================================== -->
<!-- RBVogui v3.0 -->
<robot name="rbvogui">
  <!-- ***************** -->
  <!-- Imported elements -->
  <!-- ***************** -->
  <!-- First we import all posible elements defined in the urdf.xacro files. All these elements
    are defined as macro:xacros -->
  <!-- ***************** -->
  <!-- Imported elements -->
  <!-- ***************** -->
  <!-- First we import all posible elements defined in the urdf.xacro files. All these elements are defined as macro:xacros -->
  <!-- This file unifies all sensors that can be used on simulation, defined as xacro:macros -->
  <!-- source en.wikipedia.org/wiki/List_of_moments_of_inertia-->
  <!-- $(find robotnik_sensors_gazebo)/config/camera/axis_m5013.yaml -->
  <!-- $(find robotnik_sensors_gazebo)/config/camera/axis_m5074.yaml-->
  <!-- $(find robotnik_sensors_gazebo)/config/camera/axis_m5525.yaml -->
  <!--$(find robotnik_sensors_gazebo)/config/camera/axis_m5526.yaml-->
  <!-- ***************   -->
  <!-- Robots Elements -->
  <!-- *************** -->
  <!-- Here we create the robot elements using the xacro:macros imported at the beggining of this file -->
  <!-- BASE FOOTPRINT -->
  <link name="robot_base_footprint"/>
  <joint name="robot_base_footprint_joint" type="fixed">
    <origin rpy="0 0 0" xyz="0 0 0.1165"/>
    <!-- ${wheel_radius} property must be defined inside wheel description -->
    <parent link="robot_base_footprint"/>
    <child link="robot_base_link"/>
  </joint>
  <!-- BASE_LINK -->
  <link name="robot_base_link"/>
  <!-- Chassis -->
  <joint name="robot_chassis_joint" type="fixed">
    <origin rpy="0 0 0" xyz="-0.012 0 0.1775"/>
    <parent link="robot_base_link"/>
    <child link="robot_chassis_link"/>
  </joint>
  <!-- Chassis -->
  <link name="robot_chassis_link">
    <inertial>
      <mass value="25.0"/>
      <origin xyz="0 0 0.10"/>
      <inertia ixx="1.4744666666666666" ixy="0" ixz="0" iyy="3.434635416666666" iyz="0" izz="4.707435416666667"/>
    </inertial>
    <visual>
      <origin rpy="0 0 0" xyz="0 0 0"/>
      <geometry>
        <mesh filename="package://robotnik_description/meshes/bases/rbvogui/rbvogui_chassis_color.dae"/>
      </geometry>
    </visual>
    <collision>
      <origin rpy="0 0 0 " xyz="0 0 0"/>
      <geometry>
        <mesh filename="package://robotnik_description/meshes/bases/rbvogui/rbvogui_chassis_color.dae"/>
      </geometry>
    </collision>
  </link>
  <!-- Battery -->
  <joint name="robot_battery_joint" type="fixed">
    <origin rpy="0 0 0 " xyz="0.02952 0 0"/>
    <parent link="robot_chassis_link"/>
    <child link="robot_battery_link"/>
  </joint>
  <!-- Battery -->
  <link name="robot_battery_link">
    <inertial>
      <mass value="45.0"/>
      <origin xyz="0 0 -0.05"/>
      <inertia ixx="0.06054000000000001" ixy="0" ixz="0" iyy="0.27684375000000006" iyz="0" izz="0.31038375"/>
    </inertial>
    <visual>
      <origin rpy="0 0 0" xyz="0 0 0"/>
      <geometry>
        <mesh filename="package://robotnik_description/meshes/bases/rbvogui/rbvogui_battery.stl"/>
      </geometry>
      <material name="darkgrey">
        <color rgba="0.1 0.1 0.1 1"/>
      </material>
    </visual>
    <collision>
      <origin rpy="0 0 0 " xyz="0 0 0"/>
      <geometry>
        <mesh filename="package://robotnik_description/meshes/bases/rbvogui/rbvogui_battery.stl"/>
      </geometry>
    </collision>
  </link>
  <!-- Contactors -->
  <joint name="robot_contactors_joint" type="fixed">
    <origin rpy="0 0 0 " xyz="0.5235 0 0.09265"/>
    <parent link="robot_chassis_link"/>
    <child link="robot_contactors_link"/>
  </joint>
  <!-- Contactors -->
  <link name="robot_contactors_link">
    <visual>
      <origin rpy="0 0 0" xyz="0 0 0"/>
      <geometry>
        <mesh filename="package://robotnik_description/meshes/bases/rbvogui/rbvogui_contactors.stl"/>
      </geometry>
      <material name="lighbrown">
        <color rgba="0.7 0.3 0.0 1"/>
      </material>
    </visual>
  </link>
  <!-- Logos -->
  <joint name="robot_base_logos_joint" type="fixed">
    <origin rpy="0 0 0" xyz="0 0 -0.1775"/>
    <parent link="robot_chassis_link"/>
    <child link="robot_base_logos_link"/>
  </joint>
  <!-- Logos -->
  <link name="robot_base_logos_link">
    <visual>
      <origin rpy="0 0 0 " xyz="-0.015 0 0"/>
      <geometry>
        <mesh filename="package://robotnik_description/meshes/bases/rbvogui/rbvogui_logos.stl" scale="1.001 1.076 1.001"/>
      </geometry>
      <material name="lightred">
        <color rgba="0.9 0.2 0.2 1"/>
      </material>
    </visual>
  </link>
  <!-- Leds -->
  <joint name="robot_leds_joint" type="fixed">
    <origin rpy="0 0 0 " xyz="0 0 0.1025"/>
    <parent link="robot_chassis_link"/>
    <child link="robot_leds_link"/>
  </joint>
  <link name="robot_leds_link">
    <visual>
      <origin rpy="0 0 0.0" xyz="0 0 0"/>
      <geometry>
        <mesh filename="package://robotnik_description/meshes/bases/rbvogui/rbvogui_leds.stl"/>
      </geometry>
      <material name="lightgreen">
        <color rgba="0.1 1.0 0.1 1"/>
      </material>
    </visual>
  </link>
  <gazebo reference="robot_base_link">
    <visual>
      <material>
        <ambient>0.0 0.0 0.0 1.0</ambient>
        <diffuse>0.2 0.2 0.2 1.0</diffuse>
        <specular>0.508273 0.508273 0.508273 1.0</specular>
        <emissive>0.0 0.0 0.0 0.0</emissive>
      </material>
    </visual>
  </gazebo>
  <gazebo reference="robot_battery_link">
    <visual>
      <material>
        <ambient>0.0 0.0 0.0 1.0</ambient>
        <diffuse>0.2 0.2 0.2 1.0</diffuse>
        <specular>0.508273 0.508273 0.508273 1.0</specular>
        <emissive>0.0 0.0 0.0 0.0</emissive>
      </material>
    </visual>
  </gazebo>
  <gazebo reference="robot_contactors_link">
    <visual>
      <material>
        <ambient>0.7 0.3 0.0 1.0</ambient>
        <diffuse>0.7 0.3 0.0 1.0</diffuse>
        <specular>0.7 0.3 0.0 1.0</specular>
        <emissive>0.0 0.0 0.0 0.0</emissive>
      </material>
    </visual>
  </gazebo>
  <gazebo reference="robot_base_logos_link">
    <visual>
      <material>
        <ambient>1.0 0.0 0.0 1.0</ambient>
        <diffuse>0.50754 0.50754 0.50754 1.0</diffuse>
        <specular>0.508273 0.508273 0.508273 1.0</specular>
        <emissive>0.0 0.0 0.0 0.0</emissive>
      </material>
    </visual>
  </gazebo>
  <gazebo reference="robot_leds_link">
    <visual>
      <material>
        <ambient>0.0 1.0 0.0 1.0</ambient>
        <diffuse>0.0 1.0 0.0 1.0</diffuse>
        <specular>0.0 1.0 0.0 1.0</specular>
        <emissive>0.0 0.0 0.0 0.0</emissive>
      </material>
    </visual>
  </gazebo>
  <joint name="robot_front_right_steering_joint" type="revolute">
    <parent link="robot_base_link"/>
    <child link="robot_front_right_base_wheel"/>
    <origin rpy="0 0 0" xyz="0.368 -0.235 0.0"/>
    <axis xyz="0 0 1"/>
    <limit effort="200.0" lower="-3.00" upper="3.00" velocity="100.0"/>
    <dynamics damping="1.0" friction="1.0"/>
  </joint>
  <link name="robot_front_right_base_wheel">
    <visual>
      <origin rpy="0 0 3.141592653589793" xyz="0 0 0.0"/>
      <geometry>
        <mesh filename="package://robotnik_description/meshes/wheels/steering_wheel/mw_frame_stl_color.dae"/>
      </geometry>
      <material name="red">
        <color rgba="0.9 0.1 0.1 1"/>
      </material>
    </visual>
    <collision>
      <origin rpy="0 0 3.141592653589793" xyz="0 0 0.0"/>
      <geometry>
        <mesh filename="package://robotnik_description/meshes/wheels/steering_wheel/mw_frame_stl_color.dae"/>
      </geometry>
    </collision>
    <inertial>
      <mass value="2.5"/>
      <origin rpy="1.5707963267948966 1.5707963267948966 1.5707963267948966" xyz="0 0 0.07766666666666668"/>
      <inertia ixx="0.010565989583333333" ixy="0" ixz="0" iyy="0.010565989583333333" iyz="0" izz="0.016965312500000003"/>
    </inertial>
  </link>
  <gazebo reference="robot_front_right_base_wheel">
    <mu1>0.40</mu1>
    <mu2>0.35</mu2>
    <kp>8.75e9</kp>
    <kd>8.25e0</kd>
    <fdir1>0 0 0</fdir1>
  </gazebo>
  <!--WHEEL TIRE -->
  <joint name="robot_front_right_wheel_joint" type="continuous">
    <parent link="robot_front_right_base_wheel"/>
    <child link="robot_front_right_wheel"/>
    <origin rpy="0 0 0" xyz="0 0 0"/>
    <axis xyz="0 1 0"/>
    <limit effort="100" velocity="100"/>
    <joint_properties damping="0.5" friction="2.0"/>
  </joint>
  <link name="robot_front_right_wheel">
    <visual>
      <origin rpy="0 0 0" xyz="0 0 0"/>
      <geometry>
        <mesh filename="package://robotnik_description/meshes/wheels/rubber_wheel/rubber_wheel.dae"/>
      </geometry>
    </visual>
    <collision>
      <origin rpy="1.5707963267948966 0 0" xyz="0 0 0"/>
      <geometry>
        <cylinder length="0.1375" radius="0.1165"/>
      </geometry>
    </collision>
    <inertial>
      <mass value="5.0"/>
      <origin xyz="0 0 0"/>
      <inertia ixx="0.02484291666666667" ixy="0" ixz="0" iyy="0.02484291666666667" iyz="0" izz="0.033930625000000006"/>
    </inertial>
  </link>
  <gazebo reference="robot_front_right_wheel">
    <!-- <material>Gazebo/Black</material> -->
    <mu1>0.9</mu1>
    <mu2>0.5</mu2>
    <kp>2.75e9</kp>
    <kd>8.25e1</kd>
    <fdir1>1 0 0</fdir1>
  </gazebo>
  <joint name="robot_front_left_steering_joint" type="revolute">
    <parent link="robot_base_link"/>
    <child link="robot_front_left_base_wheel"/>
    <origin rpy="0 0 0" xyz="0.368 0.235 0.0"/>
    <axis xyz="0 0 1"/>
    <limit effort="200.0" lower="-3.00" upper="3.00" velocity="100.0"/>
    <dynamics damping="1.0" friction="1.0"/>
  </joint>
  <link name="robot_front_left_base_wheel">
    <visual>
      <origin rpy="0 0 0" xyz="0 0 0.0"/>
      <geometry>
        <mesh filename="package://robotnik_description/meshes/wheels/steering_wheel/mw_frame_stl_color.dae"/>
      </geometry>
      <material name="red">
        <color rgba="0.9 0.1 0.1 1"/>
      </material>
    </visual>
    <collision>
      <origin rpy="0 0 0" xyz="0 0 0.0"/>
      <geometry>
        <mesh filename="package://robotnik_description/meshes/wheels/steering_wheel/mw_frame_stl_color.dae"/>
      </geometry>
    </collision>
    <inertial>
      <mass value="2.5"/>
      <origin rpy="1.5707963267948966 1.5707963267948966 0" xyz="0 0 0.07766666666666668"/>
      <inertia ixx="0.010565989583333333" ixy="0" ixz="0" iyy="0.010565989583333333" iyz="0" izz="0.016965312500000003"/>
    </inertial>
  </link>
  <gazebo reference="robot_front_left_base_wheel">
    <mu1>0.40</mu1>
    <mu2>0.35</mu2>
    <kp>8.75e9</kp>
    <kd>8.25e0</kd>
    <fdir1>0 0 0</fdir1>
  </gazebo>
  <!--WHEEL TIRE -->
  <joint name="robot_front_left_wheel_joint" type="continuous">
    <parent link="robot_front_left_base_wheel"/>
    <child link="robot_front_left_wheel"/>
    <origin rpy="0 0 0" xyz="0 0 0"/>
    <axis xyz="0 1 0"/>
    <limit effort="100" velocity="100"/>
    <joint_properties damping="0.5" friction="2.0"/>
  </joint>
  <link name="robot_front_left_wheel">
    <visual>
      <origin rpy="3.141592653589793 0 0" xyz="0 0 0"/>
      <geometry>
        <mesh filename="package://robotnik_description/meshes/wheels/rubber_wheel/rubber_wheel.dae"/>
      </geometry>
    </visual>
    <collision>
      <origin rpy="1.5707963267948966 0 0" xyz="0 0 0"/>
      <geometry>
        <cylinder length="0.1375" radius="0.1165"/>
      </geometry>
    </collision>
    <inertial>
      <mass value="5.0"/>
      <origin xyz="0 0 0"/>
      <inertia ixx="0.02484291666666667" ixy="0" ixz="0" iyy="0.02484291666666667" iyz="0" izz="0.033930625000000006"/>
    </inertial>
  </link>
  <gazebo reference="robot_front_left_wheel">
    <!-- <material>Gazebo/Black</material> -->
    <mu1>0.9</mu1>
    <mu2>0.5</mu2>
    <kp>2.75e9</kp>
    <kd>8.25e1</kd>
    <fdir1>1 0 0</fdir1>
  </gazebo>
  <joint name="robot_back_left_steering_joint" type="revolute">
    <parent link="robot_base_link"/>
    <child link="robot_back_left_base_wheel"/>
    <origin rpy="0 0 0" xyz="-0.368 0.235 0.0"/>
    <axis xyz="0 0 1"/>
    <limit effort="200.0" lower="-3.00" upper="3.00" velocity="100.0"/>
    <dynamics damping="1.0" friction="1.0"/>
  </joint>
  <link name="robot_back_left_base_wheel">
    <visual>
      <origin rpy="0 0 0" xyz="0 0 0.0"/>
      <geometry>
        <mesh filename="package://robotnik_description/meshes/wheels/steering_wheel/mw_frame_stl_color.dae"/>
      </geometry>
      <material name="red">
        <color rgba="0.9 0.1 0.1 1"/>
      </material>
    </visual>
    <collision>
      <origin rpy="0 0 0" xyz="0 0 0.0"/>
      <geometry>
        <mesh filename="package://robotnik_description/meshes/wheels/steering_wheel/mw_frame_stl_color.dae"/>
      </geometry>
    </collision>
    <inertial>
      <mass value="2.5"/>
      <origin rpy="1.5707963267948966 1.5707963267948966 0" xyz="0 0 0.07766666666666668"/>
      <inertia ixx="0.010565989583333333" ixy="0" ixz="0" iyy="0.010565989583333333" iyz="0" izz="0.016965312500000003"/>
    </inertial>
  </link>
  <gazebo reference="robot_back_left_base_wheel">
    <mu1>0.40</mu1>
    <mu2>0.35</mu2>
    <kp>8.75e9</kp>
    <kd>8.25e0</kd>
    <fdir1>0 0 0</fdir1>
  </gazebo>
  <!--WHEEL TIRE -->
  <joint name="robot_back_left_wheel_joint" type="continuous">
    <parent link="robot_back_left_base_wheel"/>
    <child link="robot_back_left_wheel"/>
    <origin rpy="0 0 0" xyz="0 0 0"/>
    <axis xyz="0 1 0"/>
    <limit effort="100" velocity="100"/>
    <joint_properties damping="0.5" friction="2.0"/>
  </joint>
  <link name="robot_back_left_wheel">
    <visual>
      <origin rpy="3.141592653589793 0 0" xyz="0 0 0"/>
      <geometry>
        <mesh filename="package://robotnik_description/meshes/wheels/rubber_wheel/rubber_wheel.dae"/>
      </geometry>
    </visual>
    <collision>
      <origin rpy="1.5707963267948966 0 0" xyz="0 0 0"/>
      <geometry>
        <cylinder length="0.1375" radius="0.1165"/>
      </geometry>
    </collision>
    <inertial>
      <mass value="5.0"/>
      <origin xyz="0 0 0"/>
      <inertia ixx="0.02484291666666667" ixy="0" ixz="0" iyy="0.02484291666666667" iyz="0" izz="0.033930625000000006"/>
    </inertial>
  </link>
  <gazebo reference="robot_back_left_wheel">
    <!-- <material>Gazebo/Black</material> -->
    <mu1>0.9</mu1>
    <mu2>0.5</mu2>
    <kp>2.75e9</kp>
    <kd>8.25e1</kd>
    <fdir1>1 0 0</fdir1>
  </gazebo>
  <joint name="robot_back_right_steering_joint" type="revolute">
    <parent link="robot_base_link"/>
    <child link="robot_back_right_base_wheel"/>
    <origin rpy="0 0 0" xyz="-0.368 -0.235 0.0"/>
    <axis xyz="0 0 1"/>
    <limit effort="200.0" lower="-3.00" upper="3.00" velocity="100.0"/>
    <dynamics damping="1.0" friction="1.0"/>
  </joint>
  <link name="robot_back_right_base_wheel">
    <visual>
      <origin rpy="0 0 3.141592653589793" xyz="0 0 0.0"/>
      <geometry>
        <mesh filename="package://robotnik_description/meshes/wheels/steering_wheel/mw_frame_stl_color.dae"/>
      </geometry>
      <material name="red">
        <color rgba="0.9 0.1 0.1 1"/>
      </material>
    </visual>
    <collision>
      <origin rpy="0 0 3.141592653589793" xyz="0 0 0.0"/>
      <geometry>
        <mesh filename="package://robotnik_description/meshes/wheels/steering_wheel/mw_frame_stl_color.dae"/>
      </geometry>
    </collision>
    <inertial>
      <mass value="2.5"/>
      <origin rpy="1.5707963267948966 1.5707963267948966 1.5707963267948966" xyz="0 0 0.07766666666666668"/>
      <inertia ixx="0.010565989583333333" ixy="0" ixz="0" iyy="0.010565989583333333" iyz="0" izz="0.016965312500000003"/>
    </inertial>
  </link>
  <gazebo reference="robot_back_right_base_wheel">
    <mu1>0.40</mu1>
    <mu2>0.35</mu2>
    <kp>8.75e9</kp>
    <kd>8.25e0</kd>
    <fdir1>0 0 0</fdir1>
  </gazebo>
  <!--WHEEL TIRE -->
  <joint name="robot_back_right_wheel_joint" type="continuous">
    <parent link="robot_back_right_base_wheel"/>
    <child link="robot_back_right_wheel"/>
    <origin rpy="0 0 0" xyz="0 0 0"/>
    <axis xyz="0 1 0"/>
    <limit effort="100" velocity="100"/>
    <joint_properties damping="0.5" friction="2.0"/>
  </joint>
  <link name="robot_back_right_wheel">
    <visual>
      <origin rpy="0 0 0" xyz="0 0 0"/>
      <geometry>
        <mesh filename="package://robotnik_description/meshes/wheels/rubber_wheel/rubber_wheel.dae"/>
      </geometry>
    </visual>
    <collision>
      <origin rpy="1.5707963267948966 0 0" xyz="0 0 0"/>
      <geometry>
        <cylinder length="0.1375" radius="0.1165"/>
      </geometry>
    </collision>
    <inertial>
      <mass value="5.0"/>
      <origin xyz="0 0 0"/>
      <inertia ixx="0.02484291666666667" ixy="0" ixz="0" iyy="0.02484291666666667" iyz="0" izz="0.033930625000000006"/>
    </inertial>
  </link>
  <gazebo reference="robot_back_right_wheel">
    <!-- <material>Gazebo/Black</material> -->
    <mu1>0.9</mu1>
    <mu2>0.5</mu2>
    <kp>2.75e9</kp>
    <kd>8.25e1</kd>
    <fdir1>1 0 0</fdir1>
  </gazebo>
  <!-- SENSORS see robotnik_sensors for the specific configuration -->
  <joint name="robot_vectornav_base_joint" type="fixed">
    <origin rpy="0 0 0" xyz="0.127 -0.129 0.212"/>
    <parent link="robot_base_link"/>
    <child link="robot_vectornav_base_link"/>
  </joint>
  <link name="robot_vectornav_base_link">
    <inertial>
      <origin rpy="0 0 0" xyz="0.0 0 0.01"/>
      <mass value="0.05"/>
      <inertia ixx="3.3333333333333337e-06" ixy="0" ixz="0" iyy="3.3333333333333337e-06" iyz="0" izz="3.3333333333333337e-06"/>
    </inertial>
    <visual>
      <origin rpy="0 0 0" xyz="0 0 0"/>
      <material name="vectornav_imu_color">
        <color rgba="1 0 0 1"/>
      </material>
      <geometry>
        <mesh filename="package://robotnik_sensors/meshes/imu/vectornav_vn100.stl"/>
      </geometry>
    </visual>
    <collision>
      <origin rpy="0 0 0" xyz="0 0 0.0045"/>
      <geometry>
        <box size="0.036 0.037 0.009"/>
      </geometry>
    </collision>
  </link>
  <joint name="robot_vectornav_joint" type="fixed">
    <axis xyz="1 0 0"/>
    <origin xyz="-0.00745 0.0 0.0088"/>
    <parent link="robot_vectornav_base_link"/>
    <child link="robot_vectornav_link"/>
  </joint>
  <link name="robot_vectornav_link"/>
  <gazebo reference="robot_vectornav_base_link">
    <material>Gazebo/Red</material>
  </gazebo>
  <joint name="robot_front_laser_base_joint" type="fixed">
    <origin rpy="0 -3.14159265359 -2.3561944901925003" xyz="0.53 0.33 0.1145"/>
    <parent link="robot_base_link"/>
    <child link="robot_front_laser_base_link"/>
  </joint>
  <link name="robot_front_laser_base_link">
    <visual>
      <origin rpy="-1.5707963267948966 0 0" xyz="0 0 0"/>
      <geometry>
        <mesh filename="package://robotnik_sensors/meshes/2d_lidar/sick/s300.dae"/>
      </geometry>
    </visual>
    <collision>
      <origin rpy="-1.5707963267948966 0 0" xyz="0 0 0"/>
      <geometry>
        <mesh filename="package://robotnik_sensors/meshes/2d_lidar/sick/s300.dae"/>
      </geometry>
    </collision>
    <inertial>
      <mass value="0.25"/>
      <origin rpy="0 0 0" xyz="-0.0017 0 0.042875"/>
      <inertia ixx="0.00022818880208333336" ixy="0" ixz="0" iyy="0.0002307096354166667" iyz="0" izz="0.0001525208333333333"/>
    </inertial>
  </link>
  <joint name="robot_front_laser_joint" type="fixed">
    <origin rpy="0 0 0" xyz="0.0 0 0.116"/>
    <parent link="robot_front_laser_base_link"/>
    <child link="robot_front_laser_link"/>
  </joint>
  <link name="robot_front_laser_link"/>
  <joint name="robot_rear_laser_base_joint" type="fixed">
    <origin rpy="0 -3.14159265359 0.7853981633975" xyz="-0.53 -0.33 0.1145"/>
    <parent link="robot_base_link"/>
    <child link="robot_rear_laser_base_link"/>
  </joint>
  <link name="robot_rear_laser_base_link">
    <visual>
      <origin rpy="-1.5707963267948966 0 0" xyz="0 0 0"/>
      <geometry>
        <mesh filename="package://robotnik_sensors/meshes/2d_lidar/sick/s300.dae"/>
      </geometry>
    </visual>
    <collision>
      <origin rpy="-1.5707963267948966 0 0" xyz="0 0 0"/>
      <geometry>
        <mesh filename="package://robotnik_sensors/meshes/2d_lidar/sick/s300.dae"/>
      </geometry>
    </collision>
    <inertial>
      <mass value="0.25"/>
      <origin rpy="0 0 0" xyz="-0.0017 0 0.042875"/>
      <inertia ixx="0.00022818880208333336" ixy="0" ixz="0" iyy="0.0002307096354166667" iyz="0" izz="0.0001525208333333333"/>
    </inertial>
  </link>
  <joint name="robot_rear_laser_joint" type="fixed">
    <origin rpy="0 0 0" xyz="0.0 0 0.116"/>
    <parent link="robot_rear_laser_base_link"/>
    <child link="robot_rear_laser_link"/>
  </joint>
  <link name="robot_rear_laser_link"/>
  <joint name="robot_front_rgbd_camera_base_joint" type="fixed">
    <origin rpy="0 0 0" xyz="0.46462 0.0 0.18258"/>
    <parent link="robot_base_link"/>
    <child link="robot_front_rgbd_camera_base_link"/>
  </joint>
  <link name="robot_front_rgbd_camera_base_link"/>
  <!-- camera body, with origin at bottom screw mount -->
  <joint name="robot_front_rgbd_camera_joint" type="fixed">
    <parent link="robot_front_rgbd_camera_base_link"/>
    <child link="robot_front_rgbd_camera_link"/>
    <origin rpy="0 0 0" xyz="0.01 0.02 0"/>
    <child link="robot_front_rgbd_camera_link"/>
  </joint>
  <link name="robot_front_rgbd_camera_link">
    <!-- camera link is aligned with the infrared sensor 1 that is "in the middle of the camera", not the one in the edge -->
    <visual>
      <origin rpy="1.5707963267948966 0 1.5707963267948966" xyz="0.0149 -0.0175 0"/>
      <geometry>
        <!-- <box size="${d435_cam_width} ${d435_cam_height} ${d435_cam_depth}"/> -->
        <mesh filename="package://robotnik_sensors/meshes/depth/intel_realsense_d435/intel_d435_color.dae"/>
      </geometry>
    </visual>
    <collision>
      <origin rpy="0 0 0" xyz="0 -0.0175 0"/>
      <geometry>
        <box size="0.02505 0.09 0.025"/>
      </geometry>
    </collision>
    <inertial>
      <origin rpy="0 0 0" xyz="0.0025 -0.015 0.0"/>
      <mass value="0.1"/>
      <inertia ixx="7.270833333333333e-05" ixy="0" ixz="0" iyy="1.041666666666667e-05" iyz="0" izz="7.270833333333333e-05"/>
    </inertial>
  </link>
  <!-- Use the nominal extrinsics between camera frames if the calibrated extrinsics aren't being published. e.g. running the device in simulation  -->
  <!-- camera depth joints and links -->
  <joint name="robot_front_rgbd_camera_depth_joint" type="fixed">
    <origin rpy="0 0 0" xyz="0 0 0"/>
    <parent link="robot_front_rgbd_camera_link"/>
    <child link="robot_front_rgbd_camera_depth_frame"/>
  </joint>
  <link name="robot_front_rgbd_camera_depth_frame"/>
  <joint name="robot_front_rgbd_camera_depth_optical_joint" type="fixed">
    <origin rpy="-1.5707963267948966 0 -1.5707963267948966" xyz="0 0 0"/>
    <parent link="robot_front_rgbd_camera_depth_frame"/>
    <child link="robot_front_rgbd_camera_depth_optical_frame"/>
  </joint>
  <link name="robot_front_rgbd_camera_depth_optical_frame"/>
  <!-- camera left IR joints and links -->
  <joint name="robot_front_rgbd_camera_infra1_joint" type="fixed">
    <origin rpy="0 0 0" xyz="0 0.0 0"/>
    <parent link="robot_front_rgbd_camera_link"/>
    <child link="robot_front_rgbd_camera_infra1_frame"/>
  </joint>
  <link name="robot_front_rgbd_camera_infra1_frame"/>
  <joint name="robot_front_rgbd_camera_infra1_optical_joint" type="fixed">
    <origin rpy="-1.5707963267948966 0 -1.5707963267948966" xyz="0 0 0"/>
    <parent link="robot_front_rgbd_camera_infra1_frame"/>
    <child link="robot_front_rgbd_camera_infra1_optical_frame"/>
  </joint>
  <link name="robot_front_rgbd_camera_infra1_optical_frame"/>
  <!-- camera right IR joints and links -->
  <joint name="robot_front_rgbd_camera_infra2_joint" type="fixed">
    <origin rpy="0 0 0" xyz="0 -0.05 0"/>
    <parent link="robot_front_rgbd_camera_link"/>
    <child link="robot_front_rgbd_camera_infra2_frame"/>
  </joint>
  <link name="robot_front_rgbd_camera_infra2_frame"/>
  <joint name="robot_front_rgbd_camera_infra2_optical_joint" type="fixed">
    <origin rpy="-1.5707963267948966 0 -1.5707963267948966" xyz="0 0 0"/>
    <parent link="robot_front_rgbd_camera_infra2_frame"/>
    <child link="robot_front_rgbd_camera_infra2_optical_frame"/>
  </joint>
  <link name="robot_front_rgbd_camera_infra2_optical_frame"/>
  <!-- camera color joints and links -->
  <joint name="robot_front_rgbd_camera_color_joint" type="fixed">
    <origin rpy="0 0 0" xyz="0 0.015 0"/>
    <parent link="robot_front_rgbd_camera_link"/>
    <child link="robot_front_rgbd_camera_color_frame"/>
  </joint>
  <link name="robot_front_rgbd_camera_color_frame"/>
  <joint name="robot_front_rgbd_camera_color_optical_joint" type="fixed">
    <origin rpy="-1.5707963267948966 0 -1.5707963267948966" xyz="0 0 0"/>
    <parent link="robot_front_rgbd_camera_color_frame"/>
    <child link="robot_front_rgbd_camera_color_optical_frame"/>
  </joint>
  <link name="robot_front_rgbd_camera_color_optical_frame"/>
  <joint name="robot_rear_rgbd_camera_base_joint" type="fixed">
    <origin rpy="0 0 -3.14159265359" xyz="-0.515 0.0 0.29"/>
    <parent link="robot_base_link"/>
    <child link="robot_rear_rgbd_camera_base_link"/>
  </joint>
  <link name="robot_rear_rgbd_camera_base_link"/>
  <!-- camera body, with origin at bottom screw mount -->
  <joint name="robot_rear_rgbd_camera_joint" type="fixed">
    <parent link="robot_rear_rgbd_camera_base_link"/>
    <child link="robot_rear_rgbd_camera_link"/>
    <origin rpy="0 0 0" xyz="0.01 0.02 0"/>
    <child link="robot_rear_rgbd_camera_link"/>
  </joint>
  <link name="robot_rear_rgbd_camera_link">
    <!-- camera link is aligned with the infrared sensor 1 that is "in the middle of the camera", not the one in the edge -->
    <visual>
      <origin rpy="1.5707963267948966 0 1.5707963267948966" xyz="0.0149 -0.0175 0"/>
      <geometry>
        <!-- <box size="${d435_cam_width} ${d435_cam_height} ${d435_cam_depth}"/> -->
        <mesh filename="package://robotnik_sensors/meshes/depth/intel_realsense_d435/intel_d435_color.dae"/>
      </geometry>
    </visual>
    <collision>
      <origin rpy="0 0 0" xyz="0 -0.0175 0"/>
      <geometry>
        <box size="0.02505 0.09 0.025"/>
      </geometry>
    </collision>
    <inertial>
      <origin rpy="0 0 0" xyz="0.0025 -0.015 0.0"/>
      <mass value="0.1"/>
      <inertia ixx="7.270833333333333e-05" ixy="0" ixz="0" iyy="1.041666666666667e-05" iyz="0" izz="7.270833333333333e-05"/>
    </inertial>
  </link>
  <!-- Use the nominal extrinsics between camera frames if the calibrated extrinsics aren't being published. e.g. running the device in simulation  -->
  <!-- camera depth joints and links -->
  <joint name="robot_rear_rgbd_camera_depth_joint" type="fixed">
    <origin rpy="0 0 0" xyz="0 0 0"/>
    <parent link="robot_rear_rgbd_camera_link"/>
    <child link="robot_rear_rgbd_camera_depth_frame"/>
  </joint>
  <link name="robot_rear_rgbd_camera_depth_frame"/>
  <joint name="robot_rear_rgbd_camera_depth_optical_joint" type="fixed">
    <origin rpy="-1.5707963267948966 0 -1.5707963267948966" xyz="0 0 0"/>
    <parent link="robot_rear_rgbd_camera_depth_frame"/>
    <child link="robot_rear_rgbd_camera_depth_optical_frame"/>
  </joint>
  <link name="robot_rear_rgbd_camera_depth_optical_frame"/>
  <!-- camera left IR joints and links -->
  <joint name="robot_rear_rgbd_camera_infra1_joint" type="fixed">
    <origin rpy="0 0 0" xyz="0 0.0 0"/>
    <parent link="robot_rear_rgbd_camera_link"/>
    <child link="robot_rear_rgbd_camera_infra1_frame"/>
  </joint>
  <link name="robot_rear_rgbd_camera_infra1_frame"/>
  <joint name="robot_rear_rgbd_camera_infra1_optical_joint" type="fixed">
    <origin rpy="-1.5707963267948966 0 -1.5707963267948966" xyz="0 0 0"/>
    <parent link="robot_rear_rgbd_camera_infra1_frame"/>
    <child link="robot_rear_rgbd_camera_infra1_optical_frame"/>
  </joint>
  <link name="robot_rear_rgbd_camera_infra1_optical_frame"/>
  <!-- camera right IR joints and links -->
  <joint name="robot_rear_rgbd_camera_infra2_joint" type="fixed">
    <origin rpy="0 0 0" xyz="0 -0.05 0"/>
    <parent link="robot_rear_rgbd_camera_link"/>
    <child link="robot_rear_rgbd_camera_infra2_frame"/>
  </joint>
  <link name="robot_rear_rgbd_camera_infra2_frame"/>
  <joint name="robot_rear_rgbd_camera_infra2_optical_joint" type="fixed">
    <origin rpy="-1.5707963267948966 0 -1.5707963267948966" xyz="0 0 0"/>
    <parent link="robot_rear_rgbd_camera_infra2_frame"/>
    <child link="robot_rear_rgbd_camera_infra2_optical_frame"/>
  </joint>
  <link name="robot_rear_rgbd_camera_infra2_optical_frame"/>
  <!-- camera color joints and links -->
  <joint name="robot_rear_rgbd_camera_color_joint" type="fixed">
    <origin rpy="0 0 0" xyz="0 0.015 0"/>
    <parent link="robot_rear_rgbd_camera_link"/>
    <child link="robot_rear_rgbd_camera_color_frame"/>
  </joint>
  <link name="robot_rear_rgbd_camera_color_frame"/>
  <joint name="robot_rear_rgbd_camera_color_optical_joint" type="fixed">
    <origin rpy="-1.5707963267948966 0 -1.5707963267948966" xyz="0 0 0"/>
    <parent link="robot_rear_rgbd_camera_color_frame"/>
    <child link="robot_rear_rgbd_camera_color_optical_frame"/>
  </joint>
  <link name="robot_rear_rgbd_camera_color_optical_frame"/>
  <ros2_control name="vogui" type="system">
    <hardware>
      <plugin>robotnik_base_hw/RobotnikBaseHW</plugin>
      <param name="device">can0</param>
      <param name="sync_hz">50</param>
    </hardware>
    <joint name="robot_front_left_wheel_joint">
      <param name="id">0x01</param>
      <param name="encoder_resolution">4000</param>
      <param name="gearbox_ratio">9.56</param>
      <param name="spin">1</param>
      <command_interface name="position">
        <param name="min">0.0</param>
        <param name="max">0.0</param>
      </command_interface>
      <command_interface name="velocity">
        <param name="min">-18.8495</param>
        <param name="max">18.8495</param>
      </command_interface>
      <command_interface name="effort">
        <param name="min">-50</param>
        <param name="max">50</param>
      </command_interface>
      <state_interface name="position"/>
      <state_interface name="velocity"/>
    </joint>
    <joint name="robot_back_left_wheel_joint">
      <param name="id">0x02</param>
      <param name="encoder_resolution">4000</param>
      <param name="gearbox_ratio">9.56</param>
      <param name="spin">1</param>
      <command_interface name="position">
        <param name="min">0.0</param>
        <param name="max">0.0</param>
      </command_interface>
      <command_interface name="velocity">
        <param name="min">-18.8495</param>
        <param name="max">18.8495</param>
      </command_interface>
      <command_interface name="effort">
        <param name="min">-50</param>
        <param name="max">50</param>
      </command_interface>
      <state_interface name="position"/>
      <state_interface name="velocity"/>
    </joint>
    <joint name="robot_front_right_wheel_joint">
      <param name="id">0x03</param>
      <param name="encoder_resolution">4000</param>
      <param name="gearbox_ratio">9.56</param>
      <param name="spin">-1</param>
      <command_interface name="position">
        <param name="min">0.0</param>
        <param name="max">0.0</param>
      </command_interface>
      <command_interface name="velocity">
        <param name="min">-18.8495</param>
        <param name="max">18.8495</param>
      </command_interface>
      <command_interface name="effort">
        <param name="min">-50</param>
        <param name="max">50</param>
      </command_interface>
      <state_interface name="position"/>
      <state_interface name="velocity"/>
    </joint>
    <joint name="robot_back_right_wheel_joint">
      <param name="id">0x04</param>
      <param name="encoder_resolution">4000</param>
      <param name="gearbox_ratio">9.56</param>
      <param name="spin">-1</param>
      <command_interface name="position">
        <param name="min">0.0</param>
        <param name="max">0.0</param>
      </command_interface>
      <command_interface name="velocity">
        <param name="min">-18.8495</param>
        <param name="max">18.8495</param>
      </command_interface>
      <command_interface name="effort">
        <param name="min">-50</param>
        <param name="max">50</param>
      </command_interface>
      <state_interface name="position"/>
      <state_interface name="velocity"/>
    </joint>
  </ros2_control>
</robot>
